<?xml version="1.0" encoding="utf-8" standalone="yes"?><rss version="2.0" xmlns:atom="http://www.w3.org/2005/Atom"><channel><title>archlinux on Clarity</title><link>https://111qqz.com/tags/archlinux/</link><description>Recent content in archlinux on Clarity</description><generator>Hugo -- gohugo.io</generator><language>zh-cn</language><copyright>Copyright © 2008–2018, Steve Francia and the Hugo Authors; all rights reserved.</copyright><lastBuildDate>Wed, 11 Oct 2017 16:24:11 +0000</lastBuildDate><atom:link href="https://111qqz.com/tags/archlinux/index.xml" rel="self" type="application/rss+xml"/><item><title>archlinux/manjaro fcitx 与 chrome 不兼容 中文掉字 解决办法</title><link>https://111qqz.com/2017/10/manjaro-fcitx-drop-chinese-words-randomly/</link><pubDate>Wed, 11 Oct 2017 16:24:11 +0000</pubDate><guid>https://111qqz.com/2017/10/manjaro-fcitx-drop-chinese-words-randomly/</guid><description>
[已解决]最近两个版本的 chrome（aura界面）有两个问题
https://github.com/fcitx/fcitx/issues/197
解决办法： 安装fcitx-im 包即可</description></item><item><title>manjaro(archlinux) 安装 YouCompleteMe</title><link>https://111qqz.com/2017/07/install-YouCompleteMe-on-manjaro/</link><pubDate>Fri, 28 Jul 2017 09:13:34 +0000</pubDate><guid>https://111qqz.com/2017/07/install-YouCompleteMe-on-manjaro/</guid><description>
来来回回折腾了好多次，aur直接安装或者手动编译，安装后都无法补全
ycm的log文件是在/tmp目录下的。
发现问题是缺少libtinfo.so.5
2017-07-28 17:02:12,667 - ERROR - Error occurred while loading global extra conf /home/coder/.ycm_extra_conf.py Traceback (most recent call last): File &amp;quot;/home/coder/.vim/bundle/YouCompleteMe/third_party/ycmd/ycmd/../ycmd/extra_conf_store.py&amp;quot;, line 94, in _CallGlobalExtraConfMethod module = Load( global_ycm_extra_conf, force = True ) File &amp;quot;/home/coder/.vim/bundle/YouCompleteMe/third_party/ycmd/ycmd/../ycmd/extra_conf_store.py&amp;quot;, line 173, in Load module = LoadPythonSource( _RandomName(), module_file ) File &amp;quot;/home/coder/.vim/bundle/YouCompleteMe/third_party/ycmd/ycmd/../ycmd/utils.py&amp;quot;, line 400, in LoadPythonSource return imp.load_source( name, pathname ) File &amp;quot;/home/coder/.ycm_extra_conf.py&amp;quot;, line 32, in &amp;lt;module&amp;gt; import ycm_core ImportError: libtinfo.so.5: cannot open shared object file: No such file or directory 2017-07-28 17:02:12,667 - ERROR - libtinfo.</description></item><item><title>libgfortran.so.4 missing under archlinux</title><link>https://111qqz.com/2017/06/libgfortran-so-4-missing-under-archlinux/</link><pubDate>Fri, 09 Jun 2017 20:12:41 +0000</pubDate><guid>https://111qqz.com/2017/06/libgfortran-so-4-missing-under-archlinux/</guid><description>
。。。哭了哦。。终于解决了这个bug
参考资料：
libgfortran broken?
libgfortran=3.0 should not be install with numpy &amp;lt;= 1.9
[SOLVED] libgfortran.so.3:cannot open shared object file: No such file
[Replacing gcc-libs-libs with gcc-multilib arch
conflict with gcc-libs and gcc-libs-multilib on latest update
一开始以为是anaconda相关。。。搞了半天。。。
然后又按照第一个资料里。。。试图把libgfortran用libgcc替代。。
发现删掉libgfortran会同时删掉scripy...
然后又觉得。。或许是scripy有什么问题？
查了一会也没发现什么。。。
后来又想也许是dlib的问题？
看了下dlib的github,说是pip 的安装方式可能存在问题，我又用源码安装了一边，问题依旧....
然后本来打算睡觉了。。。
突然梦到。。。也许是arch的问题呢。。。
一搜果然是。。。MGJ。。。这bug出现的时间。。。貌似是2017年5月30号以后。。。（具体参照最后一个资料的日期。。。
而且这。。。谁能想到是arch的锅啊。。。更别说是这么新鲜的bug...
所以说arch是不是不适合跑深度学习，做科学计算之类的啊orz....
最后说下解决办法：
:: gcc-libs 与 gcc-libs-multilib 有冲突。删除 gcc-libs-multilib 吗？ [y/N] y 错误：无法准备事务处理 (无法满足依赖关系) :: gcc-multilib：移除 gcc-libs-multilib 将破坏依赖关系 'gcc-libs-multilib=6.3.1-2' (tensorflow) [coder@111qqz-pc github]$ sudo pacman -S gcc-libs --force 正在解决依赖关系.</description></item></channel></rss>